Workbook

Sheet opponents_table
G1: CELESTE HARBOUR 1 | K1: CELESTE HARBOUR 2 | O1: CELESTE HARBOUR 3 | S1: CELESTE HARBOUR 4 | W1: CELESTE HARBOUR VERDANT FOREST 5 | AA1: CELESTE HARBOUR VERDANT FOREST 6 | AE1: CELESTE HARBOUR VERDANT FOREST 7 | AI1: CELESTE HARBOUR VERDANT FOREST 8 | AM1: GYM CHALLENGE 9 | AQ1: GYM CHALLENGE 10 | AU1: GYM CHALLENGE 11 | AY1: GYM CHALLENGE 12 | BC1: GYM CHALLENGE 13 | BG1: GYM CHALLENGE 14 | BK1: GYM CHALLENGE 15
G2: Morn 1 | H2: After 1 | I2: Eve 1 | J2: Nite 1 | K2: Morn 2 | L2: After 2 | M2: Eve 2 | N2: Nite 2 | O2: Morn 3 | P2: After 3 | Q2: Eve 3 | R2: Nite 3 | S2: Morn 4 | T2: After 4 | U2: Eve 4 | V2: Nite 4 | W2: Morn 5 | X2: After 5 | Y2: Eve 5 | Z2: Nite 5 | AA2: Morn 6 | AB2: After 6 | AC2: Eve 6 | AD2: Nite 6 | AE2: Morn 7 | AF2: After 7 | AG2: Eve 7 | AH2: Nite 7 | AI2: Morn8 | AJ2: After 8 | AK2: Eve 8 | AL2: Nite 8 | AM2: Morn9 | AN2: After 9 | AO2: Eve 9 | AP2: Nite 9 | AQ2: Morn10 | AR2: After 10 | AS2: Eve 10 | AT2: Nite 10 | AU2: Morn 11 | AV2: After 11 | AW2: Eve 11 | AX2: Nite 11 | AY2: Morn12 | AZ2: After 12 | BA2: Eve 12 | BB2: Nite 12 | BC2: Morn13 | BD2: After 13 | BE2: Eve 13 | BF2: Nite 13 | BG2: Morn14 | BH2: After 14 | BI2: Eve 14 | BJ2: Nite 14 | BK2: Morn 15 | BL2: After 15 | BM2: Eve 15 | BN2: Nite 15
B3: CELESTE HARBOUR | D3: New opponents added | G3: =COUNTIF(G11:G58,"✅") -> 5 | H3: =COUNTIF(H11:H58,"✅") -> 2 | I3: =COUNTIF(I11:I58,"✅") -> 2 | J3: =COUNTIF(J11:J58,"✅") -> 0 | K3: =COUNTIF(K11:K58,"✅") -> 5 | L3: =COUNTIF(L11:L58,"✅") -> 3 | M3: =COUNTIF(M11:M58,"✅") -> 4 | N3: =COUNTIF(N11:N58,"✅") -> 2 | ... BN3: =COUNTIF(BN11:BN58,"✅") -> 0
D4: Total opponents available at this time | G4: =COUNTIF(G11:G58,"✅")+COUNTIF(G11:G58,"✔️") -> 5 | H4: =COUNTIF(H11:H58,"✅")+COUNTIF(H11:H58,"✔️") -> 7 | I4: =COUNTIF(I11:I58,"✅")+COUNTIF(I11:I58,"✔️") -> 9 | J4: =COUNTIF(J11:J58,"✅")+COUNTIF(J11:J58,"✔️") -> 4 | K4: =COUNTIF(K11:K58,"✅")+COUNTIF(K11:K58,"✔️") -> 7 | L4: =COUNTIF(L11:L58,"✅")+COUNTIF(L11:L58,"✔️") -> 9 | M4: =COUNTIF(M11:M58,"✅")+COUNTIF(M11:M58,"✔️") -> 11 | N4: =COUNTIF(N11:N58,"✅")+COUNTIF(N11:N58,"✔️") -> 7 | ... BN4: =COUNTIF(BN11:BN58,"✅")+COUNTIF(BN11:BN58,"✔️") -> 10
B6: VERDANT FOREST | D6: New opponents added | G6: 0 | H6: 0 | I6: 0 | J6: 0 | K6: 0 | M6: 0 | N6: 0 | O6: 0 | P6: 0 | Q6: 0 | R6: 0 | S6: 0 | T6: 0 | U6: 0 | V6: 0 | W6: =COUNTIF(W60:W116,"✅") -> 7 | X6: =COUNTIF(X60:X116,"✅") -> 3 | Y6: =COUNTIF(Y60:Y116,"✅") -> 4 | Z6: =COUNTIF(Z60:Z116,"✅") -> 2 | AA6: =COUNTIF(AA60:AA116,"✅") -> 6 | AB6: =COUNTIF(AB60:AB116,"✅") -> 3 | AC6: =COUNTIF(AC60:AC116,"✅") -> 4 | AD6: =COUNTIF(AD60:AD116,"✅") -> 3 | ... AL6: =COUNTIF(AL60:AL116,"✅") -> 0 | AM6: =COUNTIF(AM60:AM124,"✅") -> 8 | AN6: =COUNTIF(AN60:AN116,"✅") -> 0 | AO6: =COUNTIF(AO60:AO116,"✅") -> 0 | AP6: =COUNTIF(AP60:AP116,"✅") -> 0 | AQ6: =COUNTIF(AQ60:AQ120,"✅") -> 0 | AR6: =COUNTIF(AR60:AR116,"✅") -> 0 | AS6: =COUNTIF(AS60:AS116,"✅") -> 0 | AT6: =COUNTIF(AT60:AT116,"✅") -> 0 | AU6: =COUNTIF(AU60:AU116,"✅") -> 0 | AV6: =COUNTIF(AV60:AV116,"✅") -> 0 | AW6: =COUNTIF(AW60:AW116,"✅") -> 0 | AX6: =COUNTIF(AX60:AX116,"✅") -> 0 | AY6: =COUNTIF(AY60:AY116,"✅") -> 0 | ... BB6: =COUNTIF(BB60:BB116,"✅") -> 0 | BC6: =COUNTIF(BC60:BC120,"✅") -> 0 | BD6: =COUNTIF(BD60:BD116,"✅") -> 0 | BE6: =COUNTIF(BE60:BE116,"✅") -> 0 | BF6: =COUNTIF(BF60:BF116,"✅") -> 0 | BG6: =COUNTIF(BG60:BG120,"✅") -> 0 | BH6: =COUNTIF(BH60:BH116,"✅") -> 0 | BI6: =COUNTIF(BI60:BI116,"✅") -> 0 | BJ6: =COUNTIF(BJ60:BJ116,"✅") -> 0 | BK6: =COUNTIF(BK60:BK116,"✅") -> 0 | BL6: =COUNTIF(BL60:BL116,"✅") -> 0 | BM6: =COUNTIF(BM60:BM116,"✅") -> 0 | BN6: =COUNTIF(BN60:BN116,"✅") -> 0
D7: Total opponents available at this time | G7: 0 | H7: 0 | I7: 0 | J7: 0 | K7: 0 | M7: 0 | N7: 0 | O7: 0 | P7: 0 | Q7: 0 | R7: 0 | S7: 0 | T7: 0 | U7: 0 | V7: 0 | W7: =COUNTIF(W60:W116,"✅")+COUNTIF(W60:W116,"✔️") -> 7 | X7: =COUNTIF(X60:X116,"✅")+COUNTIF(X60:X116,"✔️") -> 10 | Y7: =COUNTIF(Y60:Y116,"✅")+COUNTIF(Y60:Y116,"✔️") -> 8 | Z7: =COUNTIF(Z60:Z116,"✅")+COUNTIF(Z60:Z116,"✔️") -> 6 | AA7: =COUNTIF(AA60:AA116,"✅")+COUNTIF(AA60:AA116,"✔️") -> 15 | AB7: =COUNTIF(AB60:AB116,"✅")+COUNTIF(AB60:AB116,"✔️") -> 19 | AC7: =COUNTIF(AC60:AC116,"✅")+COUNTIF(AC60:AC116,"✔️") -> 12 | AD7: =COUNTIF(AD60:AD116,"✅")+COUNTIF(AD60:AD116,"✔️") -> 11 | ... BN7: =COUNTIF(BN60:BN116,"✅")+COUNTIF(BN60:BN116,"✔️") -> 12
D8: Total amount of new opponents added all day | G8: =SUM(G3:J3) -> 9 | K8: =SUM(K3:N3) -> 14 | O8: =SUM(O3:R3) -> 14 | S8: =SUM(S3:V3) -> 9 | W8: =SUM(W6:Z6) -> 16 | AA8: =SUM(AA6:AD6) -> 16 | AE8: =SUM(AE6:AH6) -> 15 | AI8: =SUM(AI6:AL6) -> 8 | AM8: =SUM(AM6:AP6) -> 8 | AQ8: =SUM(AQ6:AT6) -> 0 | AU8: =SUM(AU6:AX6) -> 0 | AY8: =SUM(AY6:BB6) -> 0 | BC8: =SUM(BC6:BF6) -> 0 | BG8: =SUM(BG6:BJ6) -> 0 | BK8: =SUM(BK6:BN6) -> 0
D9: Total amount of new opponents added this area | G9: =SUM(G8:V8) -> 46 | W9: =SUM(W8:AL8) -> 55 | AM9: =SUM(AM8:BB8) -> 8
D10: Total opponents across game | G10: =SUM(G8:BJ8) -> 109
B11: Opponent | C11: Prizes | D11: Count | E11: Deck | F11: Coin
A12: CELESTE HARBOUR | B12: RIVAL 1 | C12: 2 | D12: =COUNTIF(G12:AAN12,"✅")+COUNTIF(G12:AAN12,"✔️") -> 3 | E12: EEVEE DECK 1 | F12: EEVEE COIN 1 | G12: ✅ | H12: ✔️ | I12: ✔️
B13: Youngster Joey | C13: 2 | D13: =COUNTIF(G13:AAN13,"✅")+COUNTIF(G13:AAN13,"✔️") -> 11 | E13: Basic Pokemon Barrage | F13: Rattata Silver | G13: ✅ | H13: ✔️ | I13: ✔️ | K13: ✔️ | L13: ✔️ | AA13: ✔️ | AB13: ✔️ | AQ13: ✔️ | AR13: ✔️ | BG13: ✔️ | BH13: ✔️
B14: Gambler Mick | C14: 2 | D14: =COUNTIF(G14:AAN14,"✅")+COUNTIF(G14:AAN14,"✔️") -> 13 | E14: You Win Some N Lose Some | F14: Farfetchd Silver | G14: ✅ | H14: ✔️ | I14: ✔️ | M14: ✔️ | S14: ✔️ | X14: ✔️ | Y14: ✔️ | AI14: ✔️ | AN14: ✔️ | AO14: ✔️ | AY14: ✔️ | BD14: ✔️ | BE14: ✔️
B15: Schoolboy Adam | C15: 2 | D15: =COUNTIF(G15:AAN15,"✅")+COUNTIF(G15:AAN15,"✔️") -> 14 | E15: Status Infliction | F15: Drowzee Gold | G15: ✅ | H15: ✔️ | I15: ✔️ | K15: ✔️ | L15: ✔️ | S15: ✔️ | AA15: ✔️ | AB15: ✔️ | AI15: ✔️ | AQ15: ✔️ | AR15: ✔️ | AY15: ✔️ | BG15: ✔️ | BH15: ✔️
B16: Fisherman Dave | C16: 4 | D16: =COUNTIF(G16:AAN16,"✅")+COUNTIF(G16:AAN16,"✔️") -> 19 | E16: Fishy Fish | F16: Magikarp Gold | G16: ✅ | H16: ✔️ | I16: ✔️ | O16: ✔️ | W16: ✔️ | X16: ✔️ | AA16: ✔️ | AB16: ✔️ | AE16: ✔️ | AM16: ✔️ | AN16: ✔️ | AQ16: ✔️ | AR16: ✔️ | AU16: ✔️ | BC16: ✔️ | BD16: ✔️ | BG16: ✔️ | BH16: ✔️ | BK16: ✔️
B17: Fisherman John | C17: 4 | D17: =COUNTIF(G17:AAN17,"✅")+COUNTIF(G17:AAN17,"✔️") -> 16 | E17: Seavolutions | F17: Squirtle Blue | H17: ✅ | I17: ✔️ | J17: ✔️ | O17: ✔️ | S17: ✔️ | AA17: ✔️ | AB17: ✔️ | AE17: ✔️ | AI17: ✔️ | AQ17: ✔️ | AR17: ✔️ | AU17: ✔️ | AY17: ✔️ | BG17: ✔️ | BH17: ✔️ | BK17: ✔️
B18: Painter Jericho | C18: 2 | D18: =COUNTIF(G18:AAN18,"✅")+COUNTIF(G18:AAN18,"✔️") -> 16 | E18: Art Assistants | F18: Eevee Silver | H18: ✅ | I18: ✔️ | J18: ✔️ | M18: ✔️ | U18: ✔️ | V18: ✔️ | AC18: ✔️ | AD18: ✔️ | AK18: ✔️ | AL18: ✔️ | AS18: ✔️ | AT18: ✔️ | BA18: ✔️ | BB18: ✔️ | BI18: ✔️ | BJ18: ✔️
B19: Engineer Allan | C19: 3 | D19: =COUNTIF(G19:AAN19,"✅")+COUNTIF(G19:AAN19,"✔️") -> 16 | E19: Zzzap | F19: Voltorb Gold | I19: ✅ | J19: ✔️ | P19: ✔️ | Q19: ✔️ | AC19: ✔️ | AD19: ✔️ | AF19: ✔️ | AG19: ✔️ | AS19: ✔️ | AT19: ✔️ | AV19: ✔️ | AW19: ✔️ | BI19: ✔️ | BJ19: ✔️ | BL19: ✔️ | BM19: ✔️
B20: Gardener Callum | C20: 2 | D20: =COUNTIF(G20:AAN20,"✅")+COUNTIF(G20:AAN20,"✔️") -> 22 | E20: Pollen Power | F20: Bulbasaur Green 2 | I20: ✅ | J20: ✔️ | P20: ✔️ | Q20: ✔️ | U20: ✔️ | V20: ✔️ | Y20: ✔️ | Z20: ✔️ | AF20: ✔️ | AG20: ✔️ | AK20: ✔️ | AL20: ✔️ | AO20: ✔️ | AP20: ✔️ | AV20: ✔️ | AW20: ✔️ | BA20: ✔️ | BB20: ✔️ | BE20: ✔️ | BF20: ✔️ | BL20: ✔️ | BM20: ✔️
B21: RIVAL 2 | C21: 4 | D21: =COUNTIF(G21:AAN21,"✅")+COUNTIF(G21:AAN21,"✔️") -> 1 | E21: EVEEON DECK 2 | F21: EEVEE COIN 2 | K21: ✅
B22: Beach Kid Timothy | C22: 2 | D22: =COUNTIF(G22:AAN22,"✅")+COUNTIF(G22:AAN22,"✔️") -> 22 | E22: I Love Sand And Sea | F22: Diglett Brown | K22: ✅ | L22: ✔️ | O22: ✔️ | P22: ✔️ | W22: ✔️ | X22: ✔️ | AA22: ✔️ | AB22: ✔️ | AE22: ✔️ | AF22: ✔️ | AM22: ✔️ | AN22: ✔️ | AQ22: ✔️ | AR22: ✔️ | AU22: ✔️ | AV22: ✔️ | BC22: ✔️ | BD22: ✔️ | BG22: ✔️ | BH22: ✔️ | BK22: ✔️ | BL22: ✔️
B23: Beach Kid Evie | C23: 2 | D23: =COUNTIF(G23:AAN23,"✅")+COUNTIF(G23:AAN23,"✔️") -> 22 | E23: Pika And Friends | F23: Pikachu Gold | K23: ✅ | L23: ✔️ | O23: ✔️ | P23: ✔️ | W23: ✔️ | X23: ✔️ | AA23: ✔️ | AB23: ✔️ | AE23: ✔️ | AF23: ✔️ | AM23: ✔️ | AN23: ✔️ | AQ23: ✔️ | AR23: ✔️ | AU23: ✔️ | AV23: ✔️ | BC23: ✔️ | BD23: ✔️ | BG23: ✔️ | BH23: ✔️ | BK23: ✔️ | BL23: ✔️
B24: Swimmer Todd | C24: 4 | D24: =COUNTIF(G24:AAN24,"✅")+COUNTIF(G24:AAN24,"✔️") -> 12 | E24: I See Sea | F24: Tentacool Blue | K24: ✅ | L24: ✔️ | M24: ✔️ | S24: ✔️ | AB24: ✔️ | AC24: ✔️ | AI24: ✔️ | AR24: ✔️ | AS24: ✔️ | AY24: ✔️ | BH24: ✔️ | BI24: ✔️
B25: Birdspotter Tamsin | C25: 4 | D25: =COUNTIF(G25:AAN25,"✅")+COUNTIF(G25:AAN25,"✔️") -> 22 | E25: Lil Birbs | F25: Doduo Brown | K25: ✅ | L25: ✔️ | M25: ✔️ | O25: ✔️ | W25: ✔️ | X25: ✔️ | AB25: ✔️ | AC25: ✔️ | AD25: ✔️ | AE25: ✔️ | AM25: ✔️ | AN25: ✔️ | AR25: ✔️ | AS25: ✔️ | AT25: ✔️ | AU25: ✔️ | BC25: ✔️ | BD25: ✔️ | BH25: ✔️ | BI25: ✔️ | BJ25: ✔️ | BK25: ✔️
B26: Swimmer Jordan | C26: 4 | D26: =COUNTIF(G26:AAN26,"✅")+COUNTIF(G26:AAN26,"✔️") -> 11 | E26: Whirlgong | F26: Poliwag Blue | L26: ✅ | M26: ✔️ | T26: ✔️ | X26: ✔️ | Y26: ✔️ | AJ26: ✔️ | AN26: ✔️ | AO26: ✔️ | AZ26: ✔️ | BD26: ✔️ | BE26: ✔️
B27: Bug Catcher Alex | C27: 4 | D27: =COUNTIF(G27:AAN27,"✅")+COUNTIF(G27:AAN27,"✔️") -> 11 | E27: I Love Bugs! | F27: Caterpie Green | L27: ✅ | M27: ✔️ | S27: ✔️ | X27: ✔️ | Y27: ✔️ | AI27: ✔️ | AN27: ✔️ | AO27: ✔️ | AY27: ✔️ | BD27: ✔️ | BE27: ✔️
B28: Hiker Matthew | C28: 4 | D28: =COUNTIF(G28:AAN28,"✅")+COUNTIF(G28:AAN28,"✔️") -> 22 | E28: Rocks N Stones | F28: Geodude Gold | L28: ✅ | M28: ✔️ | N28: ✔️ | O28: ✔️ | S28: ✔️ | X28: ✔️ | Y28: ✔️ | Z28: ✔️ | AA28: ✔️ | AE28: ✔️ | AI28: ✔️ | AN28: ✔️ | AO28: ✔️ | AP28: ✔️ | AQ28: ✔️ | AU28: ✔️ | AY28: ✔️ | BD28: ✔️ | BE28: ✔️ | BF28: ✔️ | BG28: ✔️ | BK28: ✔️
B29: Jogger Daniel | C29: 4 | D29: =COUNTIF(G29:AAN29,"✅")+COUNTIF(G29:AAN29,"✔️") -> 11 | E29: Nido Nido Meow | F29: Nidoking Purple | M29: ✅ | N29: ✔️ | T29: ✔️ | U29: ✔️ | W29: ✔️ | AJ29: ✔️ | AK29: ✔️ | AM29: ✔️ | AZ29: ✔️ | BA29: ✔️ | BC29: ✔️
B30: Firebreather Darryl | C30: 4 | D30: =COUNTIF(G30:AAN30,"✅")+COUNTIF(G30:AAN30,"✔️") -> 15 | E30: Hot Air | F30: Magmar Red | M30: ✅ | N30: ✔️ | O30: ✔️ | S30: ✔️ | AC30: ✔️ | AD30: ✔️ | AE30: ✔️ | AI30: ✔️ | AS30: ✔️ | AT30: ✔️ | AU30: ✔️ | AY30: ✔️ | BI30: ✔️ | BJ30: ✔️ | BK30: ✔️
B31: Firebreather Kenneth | C31: 4 | D31: =COUNTIF(G31:AAN31,"✅")+COUNTIF(G31:AAN31,"✔️") -> 15 | E31: Quadrapedal Firestarters | F31: Ponyta Red | M31: ✅ | N31: ✔️ | O31: ✔️ | S31: ✔️ | AC31: ✔️ | AD31: ✔️ | AE31: ✔️ | AI31: ✔️ | AS31: ✔️ | AT31: ✔️ | AU31: ✔️ | AY31: ✔️ | BI31: ✔️ | BJ31: ✔️ | BK31: ✔️
B32: Sailor Bob | C32: 6 | D32: =COUNTIF(G32:AAN32,"✅")+COUNTIF(G32:AAN32,"✔️") -> 23 | E32: Hoist The Anchor | F32: Wartortle Blue | M32: ✅ | N32: ✔️ | P32: ✔️ | Q32: ✔️ | R32: ✔️ | Y32: ✔️ | Z32: ✔️ | AA32: ✔️ | AF32: ✔️ | AG32: ✔️ | AH32: ✔️ | AO32: ✔️ | AP32: ✔️ | AQ32: ✔️ | AV32: ✔️ | AW32: ✔️ | AX32: ✔️ | BE32: ✔️ | BF32: ✔️ | BG32: ✔️ | BL32: ✔️ | BM32: ✔️ | BN32: ✔️
B33: Psychic Brienne | C33: 6 | D33: =COUNTIF(G33:AAN33,"✅")+COUNTIF(G33:AAN33,"✔️") -> 7 | E33: Meditation Meditation | F33: Mewtwo Purple | N33: ✅ | V33: ✔️ | AD33: ✔️ | AL33: ✔️ | AT33: ✔️ | BB33: ✔️ | BJ33: ✔️
B34: Bad Dude Paul | C34: 4 | D34: =COUNTIF(G34:AAN34,"✅")+COUNTIF(G34:AAN34,"✔️") -> 7 | E34: Bad Guys | F34: Muk Purple | N34: ✅ | V34: ✔️ | Z34: ✔️ | AL34: ✔️ | AP34: ✔️ | BB34: ✔️ | BF34: ✔️
B35: RIVAL 3 | C35: 4 | D35: =COUNTIF(G35:AAN35,"✅")+COUNTIF(G35:AAN35,"✔️") -> 4 | E35: SS EEVEE | F35: EEVEE COIN 3 | O35: ✅ | P35: ✔️ | Q35: ✔️ | R35: ✔️
B36: Young Twin Anna | C36: 2 | D36: =COUNTIF(G36:AAN36,"✅")+COUNTIF(G36:AAN36,"✔️") -> 10 | E36: Pretty Plants N Butterfly | F36: Butterfree Purple | O36: ✅ | W36: ✔️ | X36: ✔️ | AE36: ✔️ | AM36: ✔️ | AN36: ✔️ | AU36: ✔️ | BC36: ✔️ | BD36: ✔️ | BK36: ✔️
B37: Young Twin Nella | C37: 2 | D37: =COUNTIF(G37:AAN37,"✅")+COUNTIF(G37:AAN37,"✔️") -> 10 | E37: Scary Plants N Bees | F37: Beedrill Green | O37: ✅ | W37: ✔️ | X37: ✔️ | AE37: ✔️ | AM37: ✔️ | AN37: ✔️ | AU37: ✔️ | BC37: ✔️ | BD37: ✔️ | BK37: ✔️
B38: Aromagirl Penelope | C38: 4 | D38: =COUNTIF(G38:AAN38,"✅")+COUNTIF(G38:AAN38,"✔️") -> 24 | E38: Strange Plants | F38: Bellsprout Green | O38: ✅ | P38: ✔️ | Q38: ✔️ | S38: ✔️ | T38: ✔️ | U38: ✔️ | AB38: ✔️ | AE38: ✔️ | AF38: ✔️ | AG38: ✔️ | AI38: ✔️ | AJ38: ✔️ | AK38: ✔️ | AR38: ✔️ | AU38: ✔️ | AV38: ✔️ | AW38: ✔️ | AY38: ✔️ | AZ38: ✔️ | BA38: ✔️ | BH38: ✔️ | BK38: ✔️ | BL38: ✔️ | BM38: ✔️
B39: Bug Catcher Frankie | C39: 4 | D39: =COUNTIF(G39:AAN39,"✅")+COUNTIF(G39:AAN39,"✔️") -> 27 | E39: Big Bad Bugs! | F39: Pinsir Brown | O39: ✅ | P39: ✔️ | Q39: ✔️ | S39: ✔️ | T39: ✔️ | U39: ✔️ | X39: ✔️ | Y39: ✔️ | AE39: ✔️ | AF39: ✔️ | AG39: ✔️ | AI39: ✔️ | AJ39: ✔️ | AK39: ✔️ | AN39: ✔️ | AO39: ✔️ | AU39: ✔️ | AV39: ✔️ | AW39: ✔️ | AY39: ✔️ | AZ39: ✔️ | BA39: ✔️ | BD39: ✔️ | BE39: ✔️ | BK39: ✔️ | BL39: ✔️ | BM39: ✔️
B40: Guitarist Jonesy | C40: 4 | D40: =COUNTIF(G40:AAN40,"✅")+COUNTIF(G40:AAN40,"✔️") -> 18 | E40: Heavy Metal | F40: Magnemite Silver | P40: ✅ | Q40: ✔️ | R40: ✔️ | W40: ✔️ | X40: ✔️ | AF40: ✔️ | AG40: ✔️ | AH40: ✔️ | AM40: ✔️ | AN40: ✔️ | AV40: ✔️ | AW40: ✔️ | AX40: ✔️ | BC40: ✔️ | BD40: ✔️ | BL40: ✔️ | BM40: ✔️ | BN40: ✔️
B41: Guitarist Howard | C41: 4 | D41: =COUNTIF(G41:AAN41,"✅")+COUNTIF(G41:AAN41,"✔️") -> 18 | E41: Rock N Shock | F41: Raichu Gold 2 | P41: ✅ | Q41: ✔️ | R41: ✔️ | W41: ✔️ | X41: ✔️ | AF41: ✔️ | AG41: ✔️ | AH41: ✔️ | AM41: ✔️ | AN41: ✔️ | AV41: ✔️ | AW41: ✔️ | AX41: ✔️ | BC41: ✔️ | BD41: ✔️ | BL41: ✔️ | BM41: ✔️ | BN41: ✔️
...

Sheet coins_table
A1: Coin | B1: Granted By
A2: abra silver | B2: =_xlfn.XLOOKUP(A2, opponents_table!F:F, opponents_table!B:B, "", 0)
A3: aerodactyl brown | B3: =_xlfn.XLOOKUP(A3, opponents_table!F:F, opponents_table!B:B, "", 0) -> Fossil Expert Jonathan
A4: aerodactyl silver | B4: =_xlfn.XLOOKUP(A4, opponents_table!F:F, opponents_table!B:B, "", 0)
A5: alakazam purple | B5: =_xlfn.XLOOKUP(A5, opponents_table!F:F, opponents_table!B:B, "", 0) -> Psychic Nova
A6: alakazam purple 2 | B6: =_xlfn.XLOOKUP(A6, opponents_table!F:F, opponents_table!B:B, "", 0)
A7: alakazam silver | B7: =_xlfn.XLOOKUP(A7, opponents_table!F:F, opponents_table!B:B, "", 0)
A8: arbok purple | B8: =_xlfn.XLOOKUP(A8, opponents_table!F:F, opponents_table!B:B, "", 0) -> Rocket Exec Petrel
A9: arcanine gold | B9: =_xlfn.XLOOKUP(A9, opponents_table!F:F, opponents_table!B:B, "", 0)
A10: arcanine red | B10: =_xlfn.XLOOKUP(A10, opponents_table!F:F, opponents_table!B:B, "", 0)
A11: arceus silver | B11: =_xlfn.XLOOKUP(A11, opponents_table!F:F, opponents_table!B:B, "", 0)
A12: articuno blue | B12: =_xlfn.XLOOKUP(A12, opponents_table!F:F, opponents_table!B:B, "", 0)
A13: azumarill blue | B13: =_xlfn.XLOOKUP(A13, opponents_table!F:F, opponents_table!B:B, "", 0)
... A419: zzzz trainerred red | B419: =_xlfn.XLOOKUP(A419, opponents_table!F:F, opponents_table!B:B, "", 0)
